Workbook

Sheet LEIA-ME
A1: INCURSION — ESTILO NA · leia isto primeiro
A3: O que este arquivo é | B3: A conversão do roster INCURSION para o estilo de jogo do Naruto-Arena: 3 unidades por time, 100 de HP para todos, orbes elementais em vez de barra de ultimate, números inteiros e fixos, zero progressão de personagem.
A4: O que mudou em uma frase | B4: Saiu tudo que fazia um jogador ser mais forte que outro fora da partida. Entrou tudo que faz uma partida ser decidida por leitura e economia de recurso.
A5: Como usar | B5: 'Regras de Combate' define o motor. 'Kits NA' é a fonte da verdade dos 100 deuses. 'Glossário' define cada palavra usada nos kits — se um efeito não está lá, ele não existe. 'Vigilância' lista o que provavelmente vai quebrar e como consertar.
A6: Convenção de cor | B6: Azul = alavanca ajustável (mexa aqui). Preto = derivado ou definição. Fundo amarelo = decisão em aberto. Fundo vermelho = risco conhecido.
A8: REMOVIDO em relação à planilha original
A9: Sistema removido | B9: Por quê
A10: Nível 1–70 · Essência de Fé · Ouro de nível | B10: Poder fora da partida. Com 100 de HP não existe granularidade: 1 ponto de dano importa, então qualquer diferença de nível decide a partida antes do turno 1.
A11: Estrela 3★–6★ e Ascensão | B11: Mesma razão. A raridade continua existindo, mas passa a significar COMPLEXIDADE do kit, não força. Um 3★ limpo tem que ganhar de um 5★ mal pilotado.
A12: Relíquias (6 slots, +15, conjuntos, Pó, Forja) | B12: Equipamento é a forma mais direta de pay-to-win num jogo simétrico.
A13: Link Divino (40 slots, Ícor, Empíreo) | B13: Min-max aleatório de status. Não há status para min-maxar.
A14: Nível de Habilidade 1→4 (Epifanias, Vislumbres) | B14: Este é o que dói remover e o mais importante. Em NA, o valor exato de cada habilidade é conhecimento público — é isso que permite ler o oponente. Habilidade com valor variável destrói a leitura e transforma o jogo em comparação de conta.
A15: Status base (HP, ATK, Atq.Mág, DEF, Def.Mág, VEL) | B15: Todos têm 100 de HP. A diferença entre um Guardião e um Atacante passa a estar no KIT (redução de dano, escudo, provocar), exatamente como em Naruto-Arena.
A16: Crítico, Evasão %, Bloqueio %, Precisão | B16: RNG que decide partidas. Foi convertido em efeitos determinísticos (ex.: 'o primeiro ataque de alvo único contra X em cada turno falha').
A17: Devoção como barra de 0→100 | B17: Virou orbe elemental. Ver 'Orbes & Elementos' — é a mudança mais importante do arquivo.
A18: Energia, Varredura, masmorras de recurso | B18: Sem progressão não há o que farmar. Energia sobrevive apenas como limite de PvE, se você quiser.
A19: Bestiário como personagem jogável 2★ / 'food' | B19: Sem sacrifício por XP, não há food. As 12 criaturas continuam, mas só como inimigos de PvE.
A21: MANTIDO
A22: Sistema mantido | B22: Como ficou
A23: Os 100 deuses, facções e nomes de habilidade | B23: Intactos. Só os efeitos foram reescritos.
A24: 6 elementos | B24: Passaram a ser os 6 tipos de orbe (o chakra do jogo). Papel muito maior que antes.
A25: 5 funções | B25: Intactas como identidade de kit: Atacante, Guardião, Suporte, Controlador, Manipulador.
A26: Físico / Mágico / Híbrido | B26: Vira CLASSE de habilidade: alvo de controle seletivo e de redução seletiva.
A27: Estrutura Básico / Habilidade / Milagre / Passiva | B27: Intacta. Cada deus tem 4 entradas.
A28: Recargas | B28: Intactas e centrais — são a moeda de tempo do jogo.
A29: Marcadores temáticos | B29: Encharcado, Dia/Noite, Combo, Disco Solar, Caudas, Atadura, Maldição, Podridão, Torpor.
A30: Gacha | B30: Mantido, mas só para ADQUIRIR deus. Nunca para fortalecer.
A31: Campanha PvE | B31: Mantida como conteúdo e como veículo das Provações de desbloqueio.
A32: ACRESCENTADO: Defesa universal | B32: 5ª ação disponível a toda unidade. 1 orbe livre, recarga 4, Invulnerável 1 turno, gasta a ação. É o slot defensivo do Naruto-Arena, com os números daquele jogo. Ver 'Regras de Combate'.
A33: ACRESCENTADO: conversão de orbe | B33: 3 orbes quaisquer → 1 do tipo escolhido, 1× por turno, sem gastar ação. Sem ela, azar de sorteio decidiria partidas e o time mono-elemento seria dominante. Ver 'Orbes & Elementos'.

Sheet Roteiro
A1: ROTEIRO — do protótipo ao jogo completo
A3: Ordenado por DEPENDÊNCIA, não por empolgação. A tentação em projeto assim é começar pelo conteúdo (os outros 91 deuses, as telas, a arte) — e é o caminho mais caro, porque cada ambiguidade que o motor revelar obriga a refazer conteúdo já produzido. A coluna 'Depende de' é a parte que importa: nada deve começar antes do que ela aponta.
A5: Onde estamos
C6: Pronto | D6: O que existe hoje
C7: Regras de combate | D7: Fechadas e documentadas: 3v3, 100 de vida, 5 opções por unidade, energia elemental, conversão 3→1, empate no turno 40.
C8: As 7 regras de resolução | D8: Decididas e implementadas: ordem no turno, redução antes do escudo, DoT antes de agir, recarga N=pula N−1, duração no turno de quem recebe, acúmulo por categoria, proteção vence controle.
C9: Roster de conteúdo | D9: 100 deuses com 4 entradas cada (400 habilidades) escritos na planilha. 9 iniciais definidos. 91 Provações escritas.
C10: Motor | D10: Função pura (estado, ação) → estado. 9 deuses implementados. 37 testes automatizados (motor, interface, auditoria contra as regras).
C11: Cliente | D11: Uma tela: batalha hot-seat, celular na horizontal, canvas 926×428 escalado. Encaixes de arte com chave em todos os elementos.
A13: O caminho
A14: # | B14: Fase | C14: Item | D14: O que é | E14: Depende de | F14: Por que nesta ordem | G14: Status
A15: FASE 0 — VALIDAR
A16: 1 | B16: 0 | C16: Jogar 10 partidas no protótipo | D16: Você contra você mesmo, atenção real. A única pergunta: um turno parece uma DECISÃO ou uma sequência óbvia? | E16: nada — pode começar agora | F16: Se a resposta for 'sequência óbvia', nada mais na lista importa. Todo o resto é multiplicador do núcleo: se o núcleo não é bom, 100 deuses são 100× de trabalho perdido. É a fase mais barata e a que mais economiza. | G16: a fazer
A17: 2 | B17: 0 | C17: Decidir 100 ou 120 de vida | D17: Jogo automatizado fecha em 8–18 turnos. Se com atenção você também fechar em ~10, o dano está alto para o tamanho da vida. | E17: jogar 10 partidas | F17: Subir a vida para 120 é uma linha de código. Cortar 400 números de dano é uma semana. Decida antes de escrever os 91 deuses restantes, porque o orçamento de dano depende disso. | G17: a fazer
A18: 3 | B18: 0 | C18: Fechar o nome dos elementos | D18: Solar/Lunar/Vital/Caos/Vazio/Tempestade (seu design) ou Tempestade/Umbra/Maré/Aurora/Chama/Verdejante (planilha). | E18: nada | F18: Renomear é trivial no dado, mas quebra ganchos temáticos: Maré aplica Encharcado, Chama aplica Queimadura, Aurora e Umbra ativam Dia e Noite. São ~60 habilidades a retraduzir. Decidir agora custa nada; decidir depois de 400 ícones de arte custa caro. | G18: a fazer
A20: FASE 1 — MOTOR
A21: 4 | B21: 1 | C21: Seleção de dois alvos ✓ | D21: PRONTO. Especificação de passos: 'inimigo', '2inimigos', 'aliado', '2aliados', 'aliado+inimigo'. Efeitos com idx apontam para o 1º ou 2º alvo. Interface pede um passo por vez, mostra ALVO 1/2 e marca o já escolhido. | E21: — | F21: Validado com Thor (22 no primeiro alvo, 12 no segundo) e Hera (buff em 2 aliados escolhidos). Junto vieram 2 primitivas que esses kits exigiam: escudo (Defesa Destrutível) e vínculo (dano dividido entre dois aliados). | G21: a fazer
A22: 5 | B22: 1 | C22: Classe por habilidade ✓ | D22: PRONTO. Cada habilidade tem classe própria: Físico, Mágico, Mental (controle) ou Aflição (dano contínuo). A Defesa é Universal e nenhum silêncio a alcança. | E22: — | F22: O silêncio agora lê a classe da HABILIDADE. Nezha tem Físico + Mental/Aflição + Mágico, então nenhum silêncio de classe cala o kit dele — é exatamente por isso que ele é o Híbrido inicial. Kits que alternam de modo trocam de classe com o modo. | G22: a fazer
A23: 6 | B23: 1 | C23: Primitivas de efeito que faltam | D23: Invocações (Shabti, Fera, clones), revives, contadores acumuláveis (Combo, Disco Solar, Caudas, Ataduras, Maldição, Podridão), estado global Dia/Noite, copiar habilidade (Ísis), dano armazenado (Xangô), contagem de morte (Yan Wong), escolha múltipla (Nüwa, Lugh, Tanuki), interceptar, contra-atacar, Vida Extra. | E23: seleção de 2 alvos | F23: São ~14 primitivas. Cada uma destrava um grupo de deuses. Implementar a primitiva ANTES do deus evita descobrir na metade que o modelo de dados não cabe. | G23: a fazer
A24: 7 | B24: 1 | C24: Arena de auto-jogo | D24: O motor roda contra si mesmo por seed, milhares de partidas, e reporta: taxa de vitória por deus, duração média, combos que fecham antes do turno 6. | E24: primitivas | F24: Isto é o que torna possível balancear 100 deuses. Intuição não escala nesse número. E como o motor é função pura com seed, o custo é baixo e o retorno é enorme: acha combo quebrado antes de qualquer humano. | G24: a fazer
A25: 8 | B25: 1 | C25: Os 91 deuses restantes | D25: Thor e Hera já entraram (2 de 91), como validação das novas capacidades. Restam 89, em lotes de ~15, rodando a arena de auto-jogo após cada lote. | E25: primitivas + arena | F25: Trabalho mecânico depois das primitivas. Estimo ~30 ambiguidades a resolver no caminho (apareceram 6 nos primeiros 9). Cada lote testado é um lote que não volta. | G25: a fazer
A26: 9 | B26: 1 | C26: Replays | D26: Guardar estado inicial + lista de ações. Reproduz qualquer partida. | E26: nada | F26: Quase de graça com motor puro e determinístico. Serve para depurar, para o jogador rever, e para investigar reclamação de balanceamento com evidência em vez de opinião. | G26: a fazer
A28: FASE 2 — CPU
A29: 10 | B29: 2 | C29: IA de busca em árvore | D29: Simula 2–3 turnos à frente, avalia vida, energia, recargas e ameaça de abate. | E29: os 91 deuses | F29: Informação perfeita, turnos discretos e poucas ações por turno: território ideal. Uma IA assim joga melhor que a maioria dos humanos no ranking baixo — 'offline é mais fácil' é escolha sua, não lei. | G29: a fazer
A30: 11 | B30: 2 | C30: Níveis de dificuldade | D30: Profundidade de busca + ruído controlado na avaliação. | E30: IA | F30: Ruído é melhor que 'burrice codificada': a IA fácil erra como um humano erra, não de formas absurdas que ensinam o jogador errado. | G30: a fazer
A32: FASE 3 — JOGO DE UM JOGADOR (primeiro produto vendável)
A33: 12 | B33: 3 | C33: Telas de coleção e montagem de time | D33: Ver os deuses que você tem, ler kits, montar e salvar times. | E33: os 91 deuses | F33: Primeira tela além da batalha. O padrão visual da tela de batalha já define a linguagem. | G33: a fazer
A34: 13 | B34: 3 | C34: Carregador de Provações | D34: Uma Provação é um estado serializado + condição de vitória. A tela lê o arquivo e monta a partida. | E34: IA + coleção | F34: O formato do estado já existe no motor. As 91 Provações estão escritas na planilha, faltando só o estado inicial de cada uma. | G34: a fazer
A35: 14 | B35: 3 | C35: Campanha | D35: 21 capítulos, bestiário como tropa, chefes com kit do roster e mais vida. | E35: IA | F35: Aqui a fantasia de poder é legítima porque o oponente é a CPU. É também onde a progressão pode voltar a existir, se você quiser. | G35: a fazer
A36: 15 | B36: 3 | C36: Persistência local | D36: Coleção, moedas, Provações completadas, progresso de campanha. | E36: coleção | F36: Sem servidor ainda. Local resolve tudo até o PvP existir. | G36: a fazer
A37: 16 | B37: 3 | C37: PORTÃO: dá para lançar | D37: Um jogo de um jogador, com combate testado, campanha e Provações, sem gacha e sem servidor. | E37: tudo acima | F37: Este é o menor produto realmente lançável. Ele valida combate, retenção e curva de dificuldade com dinheiro e risco baixos — antes de você pagar por infraestrutura. | G37: a fazer
A39: FASE 4 — SERVIDOR E PVP
A40: 17 | B40: 4 | C40: Contas e autenticação | D40: Login, recuperação, vínculo de dispositivo. | E40: portão da fase 3 | G40: a fazer
A41: 18 | B41: 4 | C41: Servidor autoritativo | D41: O MESMO motor roda no servidor; o cliente não decide nada, só desenha e envia ações. | E41: contas | F41: É o retorno do investimento em motor puro: reaproveitamento direto, e anti-cheat praticamente resolvido de brinde. | G41: a fazer
A42: 19 | B42: 4 | C42: Reconexão | D42: Retomar partida caída. | E42: servidor autoritativo | F42: Jogo por turnos torna isso simples: reenviar o estado. Em jogo de ação seria um projeto inteiro. | G42: a fazer
A43: 20 | B43: 4 | C43: Pick/ban | D43: Draft com banimento alternado antes da partida ranqueada. | E43: servidor autoritativo | F43: Última linha DECISÃO da aba Vigilância. Resolve balanceamento (o quebrado é banido), dá valor a deus de nicho como counter-pick, e é a pressão de coleção que vende amplitude sem vender poder. Sem ela o meta converge para 8 deuses e o gacha perde razão de existir. | G43: a fazer
A44: 21 | B44: 4 | C44: Pareamento e ranqueado | D44: Fila, elo, temporadas, recompensas de fim de temporada. | E44: pick/ban | G44: a fazer
A45: 22 | B45: 4 | C45: Telemetria | D45: Registro de toda partida: composições, banimentos, vitórias, duração, uso por habilidade. | E45: servidor autoritativo | F45: Faça ANTES de lançar, não depois. Sem isso você balanceia 100 deuses por opinião de fórum. Com isso, por evidência. | G45: a fazer
A47: FASE 5 — MONETIZAÇÃO
A48: 23 | B48: 5 | C48: Invocação no servidor | D48: Sorteio e teto (pity) do lado do servidor, auditável. | E48: servidor autoritativo | F48: Sorteio no cliente é fraude esperando acontecer. | G48: a fazer
...

Sheet Regras de Combate
A1: REGRAS DE COMBATE — o motor
A3: Estrutura da partida
A4: Parâmetro | B4: Valor | C4: Nota
A5: Unidades por time | B5: 3 | C5: Escolha deliberada: 3 × 4 habilidades = 12 decisões por turno. É o ponto em que o jogo é profundo e ainda legível de relance. Com 5 unidades viram 20 opções e um caos de controle.
A6: HP inicial (todos) | B6: 100 | C6: Sem exceção. Guardião e Atacante se diferenciam pelo KIT, não pela vida.
A7: Condição de vitória | B7: 3 quedas | C7: Derrote as 3 unidades inimigas.
A8: Ordem de turno | B8: alternada | C8: Você comanda as 3 unidades, depois o oponente comanda as dele. Não há iniciativa por velocidade — velocidade não existe mais.
A9: Ações por turno | B9: 1 por unidade | C9: Cada unidade viva escolhe UMA de 5 opções: Básico, Habilidade, Milagre, Defesa (universal) ou passar. A Passiva não é escolha — está sempre ativa. São 15 decisões por turno num time de 3, que é o mesmo peso do Naruto-Arena.
A10: Cronômetro de turno | B10: 60 s | C10: Alavanca. NA usava 60 s; abaixo de 45 s decisões de economia de orbe ficam impossíveis.
A11: Empate técnico | B11: turno 40 | C11: Alavanca. No turno 40, ganha quem tiver mais HP total. Sem isso, times de cura/revive fazem partidas infinitas.
A12: Aleatoriedade | B12: nenhuma no combate | C12: Não existe crítico, esquiva porcentual, bloqueio porcentual nem 'X% de chance'. O único sorteio do jogo é qual orbe você recebe.
A14: As 4 entradas de cada deus
A15: Entrada | B15: Custo padrão | C15: Regra
A16: Básico | B16: 0 ou 1 orbe | C16: Sem recarga. Sempre disponível. Um deus Silenciado só pode usar o Básico. Suportes costumam ter o Básico grátis — é isso que os torna motores de recurso em vez de dependentes.
A17: Habilidade | B17: 1 a 2 orbes | C17: Recarga 1 a 3. O coração do kit.
A18: Milagre | B18: 3 orbes (2 do elemento + 1 livre) | C18: Recarga 4 a 5. Substitui a antiga barra de 100 de Devoção. Não existe mais 'encher barra': você paga orbe, como qualquer outra coisa.
A19: Passiva | B19: grátis | C19: Sempre ativa, não gasta a ação, não pode ser removida nem silenciada (salvo se o kit disser o contrário).
A20: Defesa (universal) | B20: 1 orbe livre | C20: Recarga 4. NÃO faz parte do kit — toda unidade do jogo tem esta opção. Fica Invulnerável por 1 turno. Gasta a ação da unidade. Ver a seção dedicada abaixo.
A22: A 5ª ação: DEFESA (universal, não pertence a nenhum kit)
A23: Toda unidade do jogo, sempre, pode escolher Defesa em vez de uma das suas 4 entradas. Custa 1 orbe livre, recarga 4 turnos, e deixa a unidade Invulnerável por 1 turno. É o slot defensivo do Naruto-Arena, com os mesmos números que aquele jogo calibrou. Ela existe por três razões: dá jogada a quem está sem orbe e sem recarga; cria o jogo mental sobre comprometer um Milagre num alvo que pode ficar imune; e dá razão para dano em área existir.
A24: Regra | B24: Valor | C24: Nota
A25: Custo | B25: 1 orbe livre | C25: Qualquer tipo. Três usos numa partida custam o equivalente a um Milagre — é um preço real.
A26: Recarga | B26: 4 turnos | C26: Por unidade, não por time. Com 3 unidades você consegue proteger uma por turno em rotação — o que torna focar um alvo caro e recompensa espalhar pressão.
A27: Efeito | B27: Invulnerável por 1 turno | C27: Imune a dano novo e a efeitos novos. Continua podendo ser alvo (diferente de Inalvejável).
A28: Gasta a ação? | B28: SIM | C28: Este é o freio. Defender é abrir mão do turno daquela unidade — nada de dano, nada de cura, nada de controle. Sem isso, a Defesa seria gratuita e o jogo travaria.
A29: DoT atravessa? | B29: SIM | C29: REGRA IMPORTANTE: Veneno, Queimadura, Sangramento, Maldição e Podridão já aplicados continuam a contar durante a Invulnerabilidade. Só o dano NOVO é bloqueado. É isso que impede a rotação de Defesa de anular a ofensiva do jogo — e é o que dá nicho estrutural a Kagutsuchi, Jörmungandr, Medusa, Piranha e Ah Puch.
A30: Interage com Silenciar? | B30: não bloqueia | C30: Uma unidade Silenciada ainda pode usar Defesa — ela não é uma Habilidade. Uma unidade Atordoada, não: atordoamento tira a ação inteira.
A31: Quem ignora | B31: Odin · Shiva | C31: O Gungnir de Odin e o Terceiro Olho de Shiva ignoram Invulnerabilidade. Com a Defesa universal no jogo, esses dois deixam de ser curiosidade e passam a ser picks premium.
A33: Como o dano funciona (as 3 categorias — decore isto)
A34: Categoria | B34: Sofre redução? | C34: Regra completa
A35: Dano afetado (padrão) | B35: sim | C35: É o dano normal. Passa por redução de dano e é absorvido por Defesa Destrutível. Se a habilidade não diz nada, é este.
A36: Dano perfurante | B36: não | C36: Ignora redução de dano, MAS ainda é absorvido por Defesa Destrutível. Resposta a bruisers como Thor e Aquiles.
A37: Dano puro | B37: não | C37: Ignora redução E Defesa Destrutível. Resposta a times de escudo. Todo DoT (Veneno, Queimadura, Sangramento, Maldição, Podridão) é dano puro.
A39: Redução de dano é FLAT, não percentual. | C39: '10 de redução' significa que cada golpe recebido causa 10 menos (mínimo 0). Flat cria uma decisão real — vale a pena usar um golpe de 12 num alvo com 10 de redução? — enquanto percentual só escala e some da conta do jogador.
A41: Orçamento de números (use isto ao criar deus novo)
A42: Tipo de efeito | B42: Faixa | C42: Nota
A43: Básico — alvo único | B43: 10 a 15 | C43: 12 é o padrão; 15 para quem não tem utilidade no Básico. Básico grátis fica em 10.
A44: Habilidade — alvo único | B44: 20 a 25 | C44: 25 só se não vier com controle junto.
A45: Habilidade — área (3 alvos) | B45: 12 a 15 | C45: Área custa metade do dano de alvo único.
A46: Milagre — alvo único | B46: 32 a 40 | C46: 40 é o teto absoluto. Nada mata do HP cheio em um golpe.
...

Sheet Resolução
A1: RESOLUÇÃO — quando as coisas acontecem
A3: As 7 regras de motor. Elas não dizem o que uma habilidade FAZ (isso está em 'Kits NA'), dizem QUANDO. São invisíveis na planilha e fatais no código: é o item mais comum de matar protótipo de jogo por turnos. Todas aprovadas e implementadas no protótipo.
A5: Contexto travado
B6: Item | C6: Definição | D6: Nota
B7: Estrutura de turno | C7: Alternada, informação completa | D7: Você comanda suas 3 unidades, depois o oponente comanda as dele. Nada é oculto: ambos veem HP, orbes, recargas e efeitos. É o que permite leitura — a camada que faz o jogo ser de habilidade.
B8: Ação por unidade | C8: Uma, entre 5 opções | D8: Básico · Habilidade · Milagre · Defesa (universal) · passar. A Passiva não é escolha.
A10: As 7 regras
A11: # | B11: Regra | C11: Decisão | D11: Por quê / o que ela evita
A12: 1 | B12: Ordem de resolução no turno | C12: Na ordem que o jogador escolher, uma unidade resolvendo por vez — o estado atualiza entre elas. | D12: É a única opção que faz combo dentro do mesmo turno funcionar: Ogum destrói a Defesa Destrutível e DEPOIS Zeus explode; Sobek encharca e DEPOIS o Dilúvio bate 30. Com resolução simultânea, todo combo custaria 2 turnos e o jogo ficaria lento e raso.
A13: 2 | B13: Redução antes do escudo | C13: A redução de dano é aplicada primeiro; o que sobra é absorvido pela Defesa Destrutível. | D13: Golpe de 25 contra 10 de redução e 20 de escudo: 25−10=15 no escudo, sobram 5 de escudo, 0 de HP perdido. Na ordem inversa, redução e escudo se anulariam e investir nos dois seria desperdício — Guardião perderia a razão de existir.
A14: 3 | B14: DoT conta no início do turno de quem sofre, ANTES de agir | C14: Veneno, Queimadura, Sangramento, Maldição e Podridão contam antes da unidade escolher a ação. | D14: É o que transforma DoT num relógio de verdade: unidade com 8 de HP e 10 de Veneno morre sem agir. Parece cruel, mas é informação completa — o jogador viu chegando e escolheu não curar. É também o que faz o DoT ser a resposta estrutural à rotação de Defesa. No fim do turno, DoT seria só dano lento.
A15: 4 | B15: Recarga N = pula N−1 turnos | C15: O contador é posto em N ao usar e desconta 1 no início de cada turno seu; a habilidade libera em 0. | D15: Recarga 2 usada no turno 1 volta no turno 3. Recarga 4 (a Defesa) usada no turno 1 volta no turno 5. Recarga 1 volta no turno seguinte — de propósito, são as utilidades baratas (Ogum, Tyr, Ganesha, Nezha). Todos os números dos 100 kits assumem esta convenção.
A16: 5 | B16: Duração em turnos de quem RECEBE | C16: 'Atordoar 1 turno' = perde exatamente 1 ação. 'Buff 2 turnos' = ativo nos 2 próximos turnos do dono. Implementação: as durações descontam no FIM do turno de quem carrega o efeito. | D16: Sem ambiguidade, e é como os 400 efeitos foram escritos. Se a contagem fosse em rodadas (turno seu + turno dele), todo controle do jogo valeria o dobro do calibrado e o jogo viraria prisão.
A17: 6 | B17: Acúmulo — regra por categoria | C17: Buff/debuff de dano: SOMAM. Redução de dano: pega o MAIOR, não soma. Defesa Destrutível: SOMA. DoT de mesmo nome: renova a duração, mantém a maior magnitude — não soma. DoT de nomes diferentes: coexistem. Controle: NÃO empilha — vence o de maior duração restante. Regeneração: pega a maior. | D17: A mais importante das sete — é aqui que moram os combos que quebram jogo. Se tudo somasse, Brahma + Krishna + Nüwa chegaria a +24 de dano e o jogo viraria corrida de buff; redução somando a 30 tornaria unidades imunes à maioria das habilidades. Controle não empilhar é o que impede stunlock de duas fontes — a reclamação nº 1 do Naruto-Arena. E se nada somasse, time de Suporte deixaria de existir.
A18: 7 | B18: Proteção vence controle | C18: Regra geral: efeito de proteção prevalece sobre efeito de controle. As exceções são só as escritas nos kits — Odin e Shiva ignoram Invulnerabilidade; Hórus, Hou Yi e Boitatá ignoram Inalvejável; Perseu devolve atordoamento. Regra extra: se o provocador fica Inalvejável ou Invulnerável, o Provocar dele é SUSPENSO. | D18: Sem a regra extra, Provocar + tornar-se intocável tranca uma unidade sem nenhuma ação possível. Travamento total é o risco mais frustrante que existe neste gênero, e ele apareceria de graça pela combinação de duas habilidades que isoladamente são justas.
A20: Sequência exata de um turno (pseudocódigo do motor)
B21: 1. INÍCIO DO TURNO do jogador ativo
B22: 2. DoT conta em cada unidade dele (regra 3) — mortes aqui já valem
B23: 3. Regeneração cura em cada unidade dele
B24: 4. Recargas dele descontam 1 (regra 4)
B25: 5. Gera orbes: 1 por unidade viva, sorteado entre os elementos do time — unidades Adormecidas, Dominadas ou Submersas não geram
B26: 6. Libera 1 conversão de orbe (3→1) para este turno
B27: 7. AÇÕES — para cada unidade viva, na ordem escolhida pelo jogador (regra 1):
B28: 8. se Atordoada/Selada/Adormecida/Submersa: não age
B29: 9. escolhe Básico · Habilidade · Milagre · Defesa · passar
B30: 10. paga orbes, aplica efeito, estado atualiza IMEDIATAMENTE antes da próxima unidade
B31: 11. cálculo de dano: base + buffs − debuffs → redução (maior) → escudo (soma) → HP [regras 2 e 6]
B32: 12. FIM DO TURNO do jogador ativo
... B35: 15. passa a vez
A37: Contradições nos kits que só apareceram ao construir o motor
B38: Onde | C38: O problema | D38: Correção aplicada
B39: Nezha — Rodas de Vento e Fogo | C39: O texto dizia '+10 se Nezha já agiu neste turno'. Impossível: uma unidade age uma vez por turno. | D39: Passou a ser '+10 se outro aliado já agiu neste turno' (regra 1 dá sentido a isso: você guarda o Nezha para o fim do turno).
B40: Fujin — Companheiro de Raijin | C40: A passiva só funciona com Raijin no time, e Raijin não é inicial. Um dos 9 iniciais tem passiva morta. | D40: Mantida como está por fidelidade, e marcada como INERTE no protótipo. É uma decisão sua: ou Raijin entra nos iniciais, ou Fujin ganha uma passiva com valor autônomo.
B41: Cuca — Só Dorme de Sete em Sete Anos | C41: 'A cada 3 turnos, usa o Básico de graça' não dizia se substitui a ação ou é extra. | D41: Definido como: o Básico dela não custa orbe nesses turnos. Não é ação extra — isso quebraria a regra de 1 ação por unidade.
B42: Brigid — Ferreira Divina | C42: 'Curas curam +5 se algum inimigo estiver com Queimadura' — inimigo ou aliado? E soma com o +5 do Nefertem? | D42: Definido: qualquer unidade no campo com Queimadura ativa. Bônus de cura somam entre si (não são redução).
B43: Conversão de orbe — EXPLOIT | C43: Se todos os seus orbes fossem do MESMO tipo que você escolheu converter, a rotina não achava de onde tirar os 3 e creditava 1 orbe sem cobrar nada. Orbe de graça todo turno. | D43: Reescrita: calcula o plano de gasto primeiro, confere que soma exatamente 3, e só então credita. Se não fechar 3, devolve tudo e recusa. 30 cenários no teste automatizado.
B44: Passiva de estreia (Ganesha) | C44: 'No turno 1 o time ganha 2 orbes' disparava por turno GLOBAL, não por lado. O Jogador 2 nunca recebia — assimetria invisível que favorecia quem começava. | D44: 'Turno 1' passou a ser por LADO (flag 'estreou'). Vale para qualquer passiva de estreia no roster.
B45: Cuca — O Papão | C45: 45 de dano contra Adormecido SOMAVA com o +8 que o próprio sono concede, chegando a 53 — acima do teto de 40 documentado para Milagre de alvo único, e perto de matar do HP cheio. | D45: Reduzido para 38, que com o +8 fecha em 46. Continua sendo o maior pico do jogo, mas exige 2 turnos de preparo (dormir e depois nukear) e não mata de 100.
B46: Ganesha — Abrir Caminho | C46: A planilha dizia 'todos os buffs de 1 inimigo' e o motor fazia 'todos os buffs de TODOS'. Além de divergentes, a versão da planilha exige selecionar 2 alvos (1 aliado + 1 inimigo) numa habilidade de recarga 1. | D46: Unificado em 'remove todos os debuffs de 1 aliado e 1 BUFF DE CADA inimigo'. Orçamento equivalente, alvo único, sem precisar de seleção dupla. Seleção de 2 alvos fica para Hera e Thor, que a exigem de fato.
B47: Toque na energia gastava na hora | C47: A regra 'tocar nunca gasta' valia para habilidades, mas tocar numa pílula de energia converter 3 orbes imediatamente. Inconsistência que gerava gasto acidental. | D47: A conversão passou a seguir o mesmo modelo: 1º toque arma e mostra exatamente quais energias serão gastas; CONFIRMAR executa; CANCELAR desfaz. Nada no jogo muda de estado com um único toque.
...

Sheet Orbes & Elementos
A1: ORBES ELEMENTAIS — o chakra do jogo
A3: Esta é a maior mudança do arquivo. No original, a Devoção era uma barra que enchia sozinha até 100 e liberava o Milagre — ou seja, um recurso passivo, sem decisão. Aqui ela se torna o chakra do Naruto-Arena, usando os 6 elementos que o roster já tinha. Toda a textura estratégica do jogo nasce daqui: economizar, guardar para combo, e negar o recurso do oponente.
A5: Geração
A6: Regra | B6: Valor | C6: Detalhe
A7: Orbes por turno | B7: 1 por unidade viva | C7: Com 3 unidades vivas você recebe 3 orbes por turno. Ao perder uma unidade, você recebe 2 — perder um deus é perder economia, não só dano. Isso é o que faz uma partida virar.
A8: Tipo do orbe | B8: sorteado entre os elementos do SEU time | C8: Se o seu time é Zeus (Tempestade) + Hades (Umbra) + Atena (Aurora), você só sorteia esses 3 tipos. Time mono-elemento tem geração previsível; time arco-íris tem acesso flexível mas incerto.
A9: Acúmulo | B9: sem teto | C9: Orbe não usado fica guardado. Guardar 4 turnos para um Milagre é jogada legítima — e é exatamente onde os Manipuladores atacam.
A10: Orbe 'livre' | B10: qualquer tipo | C10: Nos custos, 'livre' significa qualquer orbe. Milagres custam '2 do elemento + 1 livre'.
A11: Custo de dois elementos | B11: não existe | C11: Nenhuma habilidade pede dois elementos diferentes específicos. Mantém o jogo legível.
A12: 6 no jogo, 3 por time | B12: consequência da regra | C12: Existem 6 elementos no roster, mas um time de 3 deuses gera no máximo 3 tipos — o sorteio só considera os elementos das unidades vivas. Três dos seis contadores ficariam em zero para sempre, então a interface exibe apenas os alcançáveis. Isso não reduz o jogo: a escolha de quais 3 elementos levar É a decisão de composição.
A14: Conversão — a saída de emergência
A15: Regra | B15: Valor | C15: Nota
A16: Taxa | B16: 3 orbes quaisquer → 1 do tipo que você escolher | C16: A taxa é ruim de propósito. Ela existe para salvar uma partida perdida por azar de sorteio, não para ser engrenagem do turno.
A17: Frequência | B17: 1× por turno | C17: Por time, não por unidade.
A18: Gasta ação? | B18: NÃO | C18: É um botão, não uma jogada. Converter e agir com as 3 unidades no mesmo turno é permitido.
A19: Bloqueável? | B19: não | C19: Nem Heimdall nem ninguém bloqueia conversão — a passiva dele impede roubo e remoção, que é outra coisa.
A20: Por que ela existe | B20: — | C20: Sem conversão, o time mono-elemento é o mais forte do jogo (sorteio previsível = combo confiável) e o time arco-íris vira armadilha. Isso mataria a razão de colecionar deuses de elementos variados — exatamente o oposto do que um gacha precisa.
A21: O que ela NÃO faz | B21: — | C21: Não apaga a diferença entre as composições. Mono-elemento continua mais confiável; arco-íris continua mais versátil e mais caro de operar. A 3:1 o custo é alto o bastante para preservar essa escolha. A 2:1 o elemento quase deixaria de importar.
A22: Paga SEMPRE 3 | B22: regra dura | C22: A rotina calcula o plano de gasto, confere que soma exatamente 3 e só então credita 1. Se não fechar 3, recusa e devolve. Sem essa trava havia um exploit: com os 3 orbes todos do tipo escolhido, o jogo creditava 1 de graça.
A23: Alvo da conversão | B23: só elementos do seu time | C23: Converter para um elemento que nenhum dos seus 3 deuses usa é sempre desperdício — as habilidades custam o elemento do próprio deus ou energia livre. A interface mostra apenas os tipos alcançáveis, por isso.
A25: Os 6 tipos e a identidade estratégica de cada um
A26: Elemento | B26: Nº no roster | C26: Identidade
A27: Tempestade | B27: =COUNTIF(Roster!$D$4:$D$103,$A27) -> 13 | C27: Dano em cadeia, manipulação de recarga e de turno. Combina com Encharcado (bônus contra alvos molhados).
A28: Umbra | B28: =COUNTIF(Roster!$D$4:$D$103,$A28) -> 27 | C28: Controle, DoT, execução, ganho de recurso ao matar. O elemento mais representado e o mais perigoso de deixar sem banimento.
A29: Maré | B29: =COUNTIF(Roster!$D$4:$D$103,$A29) -> 11 | C29: Aplica Encharcado e o explora. Habilitador — quase sempre quer um parceiro Tempestade ou Maré.
A30: Aurora | B30: =COUNTIF(Roster!$D$4:$D$103,$A30) -> 21 | C30: Cura, escudo, buff, remoção de debuff. A espinha dorsal defensiva. Ativa o DIA.
A31: Chama | B31: =COUNTIF(Roster!$D$4:$D$103,$A31) -> 13 | C31: DoT (Queimadura) e bruisers que escalam com HP perdido.
A32: Verdejante | B32: =COUNTIF(Roster!$D$4:$D$103,$A32) -> 15 | C32: Regeneração, invocação, geração de orbe, remoção de buff. O contrapeso econômico.
A33: TOTAL | B33: =SUM(B27:B32) -> 100
A35: Negação de orbe — o arquétipo mais forte do jogo
A36: Em Naruto-Arena, os times de drenar chakra dominavam o meta porque privar o oponente de recurso é mais forte que causar dano. Seu roster JÁ tinha esses personagens escritos — eles só mexiam numa barra de ultimate. Agora eles estrangulam a mão do oponente. Vigie estes: Exu (age primeiro e gera orbe de graça todo turno), Hermes e Saci (roubam 2 orbes), Dionísio e Orfeu (inimigo sob controle não gera orbe), Shuten Dōji (rouba HP e orbe), Mimir (remove orbe). Heimdall é a resposta direta: bloqueia roubo e remoção. Se você fizer um único ajuste depois de jogar, provavelmente vai ser aqui.

Sheet Iniciais
A1: OS 9 INICIAIS — grátis para todo jogador, desde a primeira partida
A3: Nove, não menos. Com 3 unidades por time, 9 deuses dão 84 combinações de formação — o jogador novo experimenta de verdade em vez de repetir o único time possível. E são poucos o bastante para que invocar continue valendo: 9 de 100.
A5: Os nove
A6: # | B6: Nome | C6: Facção | D6: Elemento | E6: Classe | F6: Função | G6: O que ensina | H6: Por que este e não outro
A7: 1 | B7: Zeus | C7: Grega | D7: Tempestade | E7: Mágico | F7: Atacante | G7: Dano em área e controle seletivo de classe (trava habilidades Mágicas). | H7: O deus mais reconhecível do jogo tem que ser grátis — é a cara do produto. E o kit é o mais didático que existe: um dano, um dano com controle, uma área com debuff, e um passivo que recompensa fechar abate.
A8: 89 | B8: Ogum | C8: Africana | D8: Verdejante | E8: Físico | F8: Atacante | G8: Como matar um tanque: dano perfurante, destruir Defesa Destrutível, dano puro. | H8: Todo jogador novo trava na primeira parede de escudo e desiste. Ogum é a resposta desenhada para isso e precisa estar disponível desde o turno zero — sem ele, o iniciante conclui que o jogo é injusto.
A9: 27 | B9: Tyr | C9: Nórdica | D9: Aurora | E9: Físico | F9: Guardião | G9: Provocar, redução de dano, e imunidade a controle para o time. | H9: Básico grátis (economia), Provocar barato, e um Milagre que salva o time de uma prisão de controle. É o antídoto do arquétipo mais frustrante do jogo, na mão de quem tem menos ferramentas.
A10: 39 | B10: Sobek | C10: Egípcia | D10: Maré | E10: Físico | F10: Guardião | G10: Submergir (tirar um inimigo do jogo por 1 turno) e explorar Encharcado. | H10: Ensina que remover um inimigo do tabuleiro por um turno vale mais que 25 de dano. E o Dilúvio batendo 30 em Encharcados dá ao iniciante a primeira sinergia que ele descobre sozinho.
A11: 95 | B11: Brigid | C11: Celta | D11: Chama | E11: Mágico | F11: Suporte | G11: Curar e causar dano no mesmo golpe; DoT; buff permanente de time. | H11: A Chama Sagrada cura os seus E queima os deles com uma ação. É a lição de eficiência de ação mais importante do jogo, e faz o iniciante entender por que uma ação vale mais que um número.
A12: 77 | B12: Ganesha | C12: Hindu | D12: Verdejante | E12: Mágico | F12: Suporte | G12: Remoção dupla (tira debuff do seu, tira buff do dele) e geração de orbe. | H12: Recarga 1 no Abrir Caminho ensina dispel nos dois sentidos, que é a resposta a metade do roster. O passivo de 2 orbes no turno 1 dá ao iniciante o primeiro gostinho de vantagem econômica.
A13: 82 | B13: Cuca | C13: Brasileira | D13: Umbra | E13: Mágico | F13: Controlador | G13: Adormecer, e o combo controle → negação de orbe. | H13: Adormecido recebe +8 de dano e não gera orbe. É a forma mais limpa de ensinar a lição central do jogo: privar o oponente de recurso vence mais partidas que causar dano.
A14: 53 | B14: Fujin | C14: Japonesa | D14: Tempestade | E14: Mágico | F14: Manipulador | G14: Guerra de recarga: atrasar a deles, adiantar a sua. | H14: Não causa quase dano nenhum e ganha partidas. É a unidade que ensina que o relógio é um recurso — e o gancho para o jogador querer o Raijin, que é o parceiro escrito no kit.
A15: 65 | B15: Nezha | C15: Chinesa | D15: Chama | E15: Híbrido | F15: Atacante | G15: Alternância de modo (Anel/Manto), imunidade a DoT, retorno após queda. | H15: O único Híbrido inicial, então o iniciante tem uma unidade que não morre para controle e redução seletivos de classe. Arsenal Celeste com recarga 1 ensina a escolher entre controle e área a cada turno.
A17: Regras que a seleção obedece
B18: Critério | C18: Como foi cumprido
B19: Os 6 elementos, todos cobertos | C19: Tempestade (Zeus, Fujin) · Verdejante (Ogum, Ganesha) · Aurora (Tyr) · Maré (Sobek) · Chama (Brigid, Nezha) · Umbra (Cuca). Sem isso, metade das habilidades do roster seria impagável para um jogador novo — o custo em orbe é do elemento do deus.
B20: As 5 funções, todas cobertas | C20: 3 Atacante · 2 Guardião · 2 Suporte · 1 Controlador · 1 Manipulador. Um só Controlador nominal, mas o controle está distribuído: Sobek submerge, Tyr provoca, Fujin trava recarga, Zeus trava habilidades Mágicas.
B21: Toda resposta essencial presente | C21: Contra tanque: Ogum (perfurante, destrói escudo, dano puro). Contra prisão de controle: Tyr e Ganesha. Contra cura: Ogum e Brigid. Contra economia: Cuca e Fujin. Se qualquer uma faltasse, o iniciante concluiria que o jogo é pay-to-win — e estaria certo.
B22: Nenhum kit de complexidade alta | C22: Sem revive, sem execução, sem contador acumulável, sem estado global de campo. O jogador aprende essas mecânicas SOFRENDO com elas primeiro, que é a forma certa de aprender.
B23: 9 panteões diferentes | C23: Só a Maia fica de fora — e ela é o Ato II da campanha, então aparece cedo de todo jeito. O jogador vê a amplitude cultural do jogo na primeira hora.
B24: Uma unidade Híbrido | C24: Nezha. Sem ela, todo o time inicial seria Físico ou Mágico e morreria inteiro para controle e redução seletivos de classe (Zeus trava Mágico, Oni reduz Mágico, Aquiles apanha de Manipulador).
B25: Time inicial competitivo, não só funcional | C25: Ogum + Tyr + Brigid ganha de composições montadas com deuses invocados. Isso é obrigatório: se o iniciante não conseguir ganhar nada, ele não fica para invocar depois.
A27: Três times iniciais que funcionam (dê estes como sugestão no tutorial)
B28: Time | C28: Como joga
B29: Ogum · Tyr · Brigid | C29: O time honesto. Tyr provoca e absorve, Brigid cura e queima ao mesmo tempo, Ogum abre qualquer defesa. Geração de orbe: Verdejante, Aurora, Chama — previsível o bastante para planejar o Milagre do Ogum.
B30: Cuca · Fujin · Zeus | C30: O time de negação. Cuca adormece (o alvo para de gerar orbe), Fujin empurra as recargas inimigas, Zeus trava habilidades Mágicas e limpa. O oponente passa a partida sem poder agir. É o time que ensina que recurso vence dano — e o mais odiado.
B31: Sobek · Nezha · Ganesha | C31: O time de tempo. Sobek submerge um inimigo por turno, Nezha alterna trava e área, Ganesha limpa e adianta recarga. Sinergia escondida: Sobek encharca, e o Dilúvio dele bate 30 em Encharcado.
A33: Alavanca: se o playtest mostrar que 9 é pouco, o próximo a entrar é Bragi (buff simples, Básico grátis). Se for muito, o primeiro a sair é Nezha — é o kit mais denso dos nove.

Sheet Provações
A1: PROVAÇÕES — as 91 rotas gratuitas de desbloqueio
A2: As regras do sistema (formato, níveis, gates, Defesa do inimigo) estão na aba 'Aquisição'. Esta aba é só a lista. Use os filtros do cabeçalho para ordenar por nível, facção ou requisito.
A3: # | B3: Deus | C3: Facção | D3: Nível | E3: Dif. | F3: Título da Provação | G3: Time inimigo (fixo) | H3: Condição de vitória | I3: Requisito
A4: 2 | B4: Hades | C4: Grega | D4: Ordália | E4: 3 | F4: O Portão Não Se Abre | G4: Bennu · Nezha · Chang'e (os três voltam da morte) | H4: Elimine os três em definitivo. Bennu e Nezha renascem; Chang'e não cai abaixo de 1 de HP. Só a execução dos Portões do Submundo e as Correntes do Tártaro resolvem — você tem 3 usos do Milagre em 14 turnos. | I4: Cap. 8
A5: 3 | B5: Poseidon | C5: Grega | D5: Provação | E5: 2 | F5: A Maré Não Espera | G5: Kagutsuchi · Mula sem Cabeça · Hércules | H5: Vença em 8 turnos. Cada inimigo tem de estar Encharcado no momento em que cai — se algum morrer seco, a Provação falha. | I5: —
A6: 4 | B6: Atena | C6: Grega | D6: Ordália | E6: 3 | F6: Nenhum Escudo Cai | G6: Ogum · Aquiles · Tyr (os três atravessam escudo) | H6: Vença sem perder um aliado, contra o time desenhado para anular a Égide: Ogum destrói Defesa Destrutível, Aquiles causa dano puro, o dano de Tyr não pode ser reduzido nem absorvido. Você não pode usar o Milagre. | I6: Possuir 12 deuses
A7: 5 | B7: Ares | C7: Grega | D7: Rito | E7: 1 | F7: Sangue por Sangue | G7: Autômato de Bronze · Golem Rúnico · Guardião do Bosque | H7: Vença com Ares abaixo de 30 de HP no golpe final. Curar Ares acima de 60 anula a Provação — ele precisa apanhar para bater. | I7: —
A8: 6 | B8: Apolo | C8: Grega | D8: Provação | E8: 2 | F8: A Aurora Não Erra | G8: Medusa · Jörmungandr · Kagutsuchi (Veneno e Queimadura em tudo) | H8: Vença em 10 turnos sem perder um aliado. Apolo é o único curandeiro e você não pode usar o Milagre dele — só a Canção da Cura, recarga 2, contra três fontes de DoT. | I8: —
A9: 7 | B9: Afrodite | C9: Grega | D9: Ordália | E9: 3 | F9: Que Se Matem | G9: Kali · Durga · Hórus (dano altíssimo) | H9: Pelo menos dois dos três inimigos têm de ser derrotados por aliados deles, via Encanto ou Paixão Fatal. Abate feito pelo seu time não conta para esses dois. | I9: Cap. 6
A10: 8 | B10: Hera | C10: Grega | D10: Provação | E10: 2 | F10: O Juramento | G10: Zeus · Perseu · Durga (explosão de alvo único) | H10: Vença sem perder um aliado, e o Juramento Nupcial tem de estar ativo no turno em que o último inimigo cai. | I10: —
A11: 9 | B11: Deméter | C11: Grega | D11: Provação | E11: 2 | F11: A Colheita Retorna | G11: Ammit · Anúbis · Hel (os três bloqueiam revive) | H11: Você começa com dois aliados já caídos. Traga os dois de volta e vença — mas Ammit impede revive de quem ela matou, Anúbis sela e Hel marca. Você tem de limpar as marcas antes de reviver. | I11: —
A12: 10 | B12: Dionísio | C12: Grega | D12: Provação | E12: 2 | F12: O Banquete | G12: Rá · Brahma · Itzamná (os três acumulam recurso) | H12: Vença sem que nenhum inimigo consiga usar um único Milagre em 12 turnos. Silêncio, Bacanal e o passivo de negação de orbe são as únicas ferramentas. | I12: —
A13: 11 | B13: Hermes | C13: Grega | D13: Ordália | E13: 3 | F13: Roubo Perfeito | G13: Heimdall · Exu · Oxum (Heimdall bloqueia roubo) | H13: Você começa com 0 orbes e não recebe geração nenhuma na partida — só pode gastar orbe roubado. E Heimdall bloqueia roubo enquanto vive, então ele tem de cair primeiro, com o Básico. | I13: Possuir 20 deuses
A14: 12 | B14: Hércules | C14: Grega | D14: Provação | E14: 2 | F14: Os Doze Trabalhos | G14: Ymir · Golem Rúnico · Thor (muito HP e redução) | H14: O golpe final tem de ser Os Doze Trabalhos com no mínimo 5 acúmulos (+20 de dano). Usar o Milagre em qualquer momento anula a Provação — a paciência é o teste. | I14: —
A15: 13 | B15: Aquiles | C15: Grega | D15: Provação | E15: 2 | F15: O Calcanhar | G15: Hermes · Loki · Saci (três Manipuladores: +10 de dano contra Aquiles) | H15: Vença sem que Aquiles caia abaixo de 40 de HP, contra o único tipo de unidade que fura a passiva dele. | I15: —
... A94: 100 | B94: Itzamná | C94: Maia | D94: Provação | E94: 2 | F94: A Escrita Sagrada | G94: Ah Puch · Khonshu · Fujin (os três atacam HP máximo e recarga) | H94: Vença sem que nenhum aliado termine a partida com HP máximo reduzido, e com no mínimo 4 acúmulos de Escrita Sagrada em um aliado. | I94: —

Sheet Roster
A1: ROSTER — 100 deuses jogáveis (sem raridade de poder)
A2: A coluna Raridade foi removida de propósito. Se ela voltar, deve significar COMPLEXIDADE do kit (quantas peças móveis o jogador precisa gerenciar), nunca força — e não pode aparecer na tela de partida.
A3: # | B3: Nome | C3: Facção | D3: Elemento | E3: Classe | F3: Função | G3: Arquétipo
A4: 1 | B4: Zeus | C4: Grega | D4: Tempestade | E4: Mágico | F4: Atacante | G4: Nuker de área
A5: 2 | B5: Hades | C5: Grega | D5: Umbra | E5: Mágico | F5: Controlador | G5: Executor sombrio
A6: 3 | B6: Poseidon | C6: Grega | D6: Maré | E6: Mágico | F6: Atacante | G6: DPS em área
A7: 4 | B7: Atena | C7: Grega | D7: Aurora | E7: Mágico | F7: Suporte | G7: Buffer/escudo
A8: 5 | B8: Ares | C8: Grega | D8: Chama | E8: Físico | F8: Atacante | G8: Bruiser com roubo de vida
A9: 6 | B9: Apolo | C9: Grega | D9: Aurora | E9: Mágico | F9: Atacante | G9: DPS à distância / cura
A10: 7 | B10: Afrodite | C10: Grega | D10: Aurora | E10: Mágico | F10: Controlador | G10: Charmer
A11: 8 | B11: Hera | C11: Grega | D11: Tempestade | E11: Mágico | F11: Suporte | G11: Buffer/protetora
A12: 9 | B12: Deméter | C12: Grega | D12: Verdejante | E12: Mágico | F12: Suporte | G12: Curandeira
A13: 10 | B13: Dionísio | C13: Grega | D13: Verdejante | E13: Mágico | F13: Controlador | G13: Debuffer/confusão
A14: 11 | B14: Hermes | C14: Grega | D14: Tempestade | E14: Físico | F14: Manipulador | G14: Velocidade/turnos
A15: 12 | B15: Hércules | C15: Grega | D15: Chama | E15: Físico | F15: Guardião | G15: Bruiser resistente
... A103: 100 | B103: Itzamná | C103: Maia | D103: Aurora | E103: Mágico | F103: Suporte | G103: Sábio (recarga/cura)

Sheet Kits NA
A1: KITS — ESTILO NA · fonte da verdade. Todo deus: 100 de HP.
A2: Números são inteiros absolutos, não porcentagens de atributo — não existem mais atributos. 'livre' = orbe de qualquer elemento. '—' no custo = grátis. Recarga em turnos. Todo efeito usado aqui está definido no Glossário; nada fora dele é válido.
A3: # | B3: Nome | C3: Facção | D3: Elemento | E3: Classe | F3: Função | G3: BÁSICO | H3: custo | I3: efeito | J3: HABILIDADE | K3: custo | L3: rec. | M3: efeito | N3: MILAGRE | O3: custo | P3: rec. | Q3: efeito | R3: PASSIVA | S3: efeito
A4: 1 | B4: Zeus | C4: Grega | D4: Tempestade | E4: Mágico | F4: Atacante | G4: Cetro do Trovão | H4: 1 Tempestade | I4: 15 de dano a 1 inimigo. | J4: Julgamento do Trovão | K4: 2 Tempestade | L4: 2 | M4: 25 de dano a 1 inimigo; ele não pode usar habilidades Mágicas por 1 turno. | N4: Ira Celestial | O4: 2 Tempestade + 1 livre | P4: 4 | Q4: 20 de dano a todos os inimigos; eles causam 5 menos de dano por 2 turnos. | R4: Soberano | S4: Ao derrotar um inimigo, Zeus ganha 1 orbe de Tempestade.
A5: 2 | B5: Hades | C5: Grega | D5: Umbra | E5: Mágico | F5: Controlador | G5: Toque Fúnebre | H5: 1 Umbra | I5: 15 de dano a 1 inimigo. | J5: Correntes do Tártaro | K5: 2 Umbra | L5: 3 | M5: 1 inimigo fica Selado por 1 turno (só Básico) e sofre 10 de dano puro por turno durante 2 turnos. | N5: Portões do Submundo | O5: 2 Umbra + 1 livre | P5: 4 | Q5: 40 de dano a 1 inimigo; se ele estiver com 20 ou menos de HP, é eliminado. Rouba 1 orbe. | R5: Ceifador de Almas | S5: Quando qualquer inimigo é derrotado, Hades cura 15 e o time ganha 1 orbe de Umbra.
A6: 3 | B6: Poseidon | C6: Grega | D6: Maré | E6: Mágico | F6: Atacante | G6: Golpe do Tridente | H6: 1 Maré | I6: 15 de dano a 1 inimigo. | J6: Tridente Colossal | K6: 2 Maré | L6: 2 | M6: 22 de dano a 2 inimigos; aplica Encharcado por 2 turnos. | N6: Maremoto | O6: 2 Maré + 1 livre | P6: 4 | Q6: 20 de dano a todos os inimigos; aplica Encharcado por 2 turnos. | R6: Regente das Marés | S6: Poseidon causa +5 de dano contra alvos Encharcados; aliados Maré recebem 5 de redução de dano.
A7: 4 | B7: Atena | C7: Grega | D7: Aurora | E7: Mágico | F7: Suporte | G7: Lança de Prata | H7: 1 Aurora | I7: 12 de dano a 1 inimigo. | J7: Égide | K7: 2 Aurora | L7: 2 | M7: 1 aliado ganha 25 de Defesa Destrutível por 2 turnos; enquanto durar, quem o atingir com habilidade Física sofre 10 de dano. | N7: Estratégia Divina | O7: 2 Aurora + 1 livre | P7: 4 | Q7: Remove todos os debuffs do time; o time causa +8 de dano por 2 turnos. | R7: Sabedoria Tática | S7: O time começa a partida com 1 orbe de Aurora extra; o time causa +5 de dano contra inimigos sob controle.
A8: 5 | B8: Ares | C8: Grega | D8: Chama | E8: Físico | F8: Atacante | G8: Golpe Sanguinário | H8: 1 Chama | I8: 15 de dano a 1 inimigo; Ares cura 6. | J8: Sede de Sangue | K8: 2 Chama | L8: 1 | M8: 22 de dano a 1 inimigo, +1 de dano por cada 4 de HP que falta em Ares. | N8: Massacre | O8: 2 Chama + 1 livre | P8: 3 | Q8: 4 golpes de 12 no mesmo alvo; se o alvo for derrotado, a recarga do Massacre zera. | R8: Fúria Marcial | S8: Ares causa +1 de dano por cada 10 de HP perdido.
A9: 6 | B9: Apolo | C9: Grega | D9: Aurora | E9: Mágico | F9: Atacante | G9: Flecha Solar | H9: 1 Aurora | I9: 15 de dano a 1 inimigo. | J9: Canção da Cura | K9: 1 Aurora + 1 livre | L9: 2 | M9: Cura 25 em 1 aliado e remove Veneno, Queimadura e Sangramento dele. | N9: Alvorada Radiante | O9: 2 Aurora + 1 livre | P9: 4 | Q9: 20 de dano a todos os inimigos; o time cura 12. | R9: Presságio | S9: Apolo causa +6 de dano contra inimigos com HP cheio (100).
A10: 7 | B10: Afrodite | C10: Grega | D10: Aurora | E10: Mágico | F10: Controlador | G10: Sussurro Encantado | H10: 1 Aurora | I10: 12 de dano a 1 inimigo. | J10: Encanto | K10: 2 Aurora | L10: 3 | M10: Domina 1 inimigo por 1 turno: ele usa o próprio Básico contra um aliado dele (você escolhe o alvo). | N10: Paixão Fatal | O10: 1 Aurora + 2 livres | P10: 4 | Q10: Todos os inimigos causam 10 menos de dano por 2 turnos e têm a Habilidade travada por 1 turno. | R10: Beleza Irresistível | S10: Ataques de alvo único contra Afrodite causam 5 menos de dano.
A11: 8 | B11: Hera | C11: Grega | D11: Tempestade | E11: Mágico | F11: Suporte | G11: Cetro Real | H11: 1 Tempestade | I11: 12 de dano a 1 inimigo. | J11: Bênção Real | K11: 2 Tempestade | L11: 2 | M11: 2 aliados causam +8 de dano e recebem 10 de redução de dano por 2 turnos. | N11: Juramento Nupcial | O11: 1 Tempestade + 2 livres | P11: 4 | Q11: Vincula 2 aliados por 2 turnos: o dano recebido por qualquer um é dividido entre os dois, e ambos ficam imunes a controle. | R11: Rainha Ciumenta | S11: Sempre que um aliado é curado, ele ganha 10 de Defesa Destrutível.
A12: 9 | B12: Deméter | C12: Grega | D12: Verdejante | E12: Mágico | F12: Suporte | G12: Foice de Ouro | H12: — | I12: 10 de dano a 1 inimigo. | J12: Dádiva da Terra | K12: 2 Verdejante | L12: 2 | M12: O time regenera 12 de HP por turno durante 2 turnos. | N12: Estação Eterna | O12: 2 Verdejante + 1 livre | P12: 4 | Q12: Revive 1 aliado caído com 40 de HP; se ninguém caiu, cura 25 no time. | R12: Ciclo das Estações | S12: No início de cada turno, o aliado mais ferido cura 6.
A13: 10 | B13: Dionísio | C13: Grega | D13: Verdejante | E13: Mágico | F13: Controlador | G13: Taça Derramada | H13: — | I13: 10 de dano a 1 inimigo. | J13: Delírio | K13: 2 Verdejante | L13: 2 | M13: 1 inimigo é Silenciado por 1 turno (só Básico) e o time inimigo perde 1 orbe. | N13: Bacanal | O13: 2 Verdejante + 1 livre | P13: 4 | Q13: No próximo turno, todos os inimigos usam o Básico contra aliados deles (você escolhe os alvos). | R13: Êxtase | S13: Inimigos Silenciados, Dominados ou Adormecidos não geram orbes.
A14: 11 | B14: Hermes | C14: Grega | D14: Tempestade | E14: Físico | F14: Manipulador | G14: Golpe Alado | H14: 1 Tempestade | I14: 2 golpes de 8 em 1 inimigo (16 total). | J14: Passo Alado | K14: 1 Tempestade | L14: 1 | M14: Todas as recargas de 1 aliado são reduzidas em 1 turno. | N14: Roubo Divino | O14: 1 Tempestade + 2 livres | P14: 4 | Q14: Rouba 2 orbes do inimigo e remove 1 buff de cada inimigo. | R14: Mensageiro | S14: Hermes age primeiro no turno 1; ataques de alvo único contra ele causam 5 menos de dano.
A15: 12 | B15: Hércules | C15: Grega | D15: Chama | E15: Físico | F15: Guardião | G15: Punho Hercúleo | H15: 1 Chama | I15: 15 de dano a 1 inimigo. | J15: Os Doze Trabalhos | K15: 2 Chama | L15: 2 | M15: 20 de dano a 1 inimigo; +4 de dano permanente a cada uso na partida. | N15: Força Sobre-humana | O15: 2 Chama + 1 livre | P15: 4 | Q15: 40 de dano perfurante a 1 inimigo (ignora redução de dano). | R15: Coragem Mortal | S15: 1× por partida, Hércules sobrevive a um golpe letal com 1 de HP.
... A103: 100 | B103: Itzamná | C103: Maia | D103: Aurora | E103: Mágico | F103: Suporte | G103: Glifo Sagrado | H103: — | I103: 12 de dano a 1 inimigo. | J103: Escrita Sagrada | K103: 1 Aurora | L103: 1 | M103: 1 aliado tem todas as recargas reduzidas em 1 turno e causa +5 de dano por 2 turnos (acumulável). | N103: Aurora da Criação | O103: 2 Aurora + 1 livre | P103: 4 | Q103: Cura 25 no time, restaura todo HP máximo perdido (Podridão) e remove todos os debuffs. | R103: Guardião do Dia | S103: Curas no time curam +5; durante o DIA, o time ganha 1 orbe extra por turno.

Sheet Glossário
A1: GLOSSÁRIO DE EFEITOS — lista fechada
A2: Regra de ouro: se um efeito não está nesta lista, ele não existe. A lista original tinha 45+ marcadores, muitos com sobreposição e muitos baseados em porcentagem de chance. Esta versão tem menos entradas, todas determinísticas, e cada uma faz uma coisa distinta.
A4: CONTROLE
B5: Efeito | C5: Regra
B6: Atordoar | C6: A unidade perde a ação inteira no próximo turno. Ainda gera orbe.
B7: Petrificar | C7: Atordoamento de 2 turnos. Só existe via Milagre.
B8: Selar | C8: Igual a Atordoar, mas de tema morte/atadura — importa porque alguns kits leem 'Selado' (ex.: Ammit).
B9: Silenciar | C9: Só pode usar o Básico. Bloqueia Habilidade, Milagre e escolhas.
B10: Provocar | C10: Só pode atacar quem provocou. Não afeta habilidades de área.
B11: Pacificar | C11: Pode agir normalmente, mas todo dano que causa é 0.
B12: Adormecer | C12: Perde a ação; acorda ao sofrer dano de Habilidade ou Milagre (DoT e Básico não acordam).
B13: Dominar | C13: No próximo turno, a unidade usa o próprio Básico contra um aliado dela. Quem controla escolhe o alvo.
B14: Medo | C14: Causa 8 menos de dano e não pode usar Milagre. Duração 2 turnos.
B15: Enraizar / Agarrar | C15: Não pode usar Habilidade nem Milagre. O Básico continua liberado.
B16: Submergir / Banir | C16: Sai do combate por 1 turno: não age, não pode ser alvo, não sofre DoT, mas também não gera orbe.
B17: Travar habilidade | C17: Uma entrada específica (Habilidade OU Milagre) fica indisponível pela duração. Não é Silenciar.
A19: DEFESA
B20: Efeito | C20: Regra
B21: Defesa Destrutível | C21: Reserva numérica que absorve dano antes do HP. Escudos de fontes diferentes somam. Não bloqueia dano puro.
B22: Redução de dano | C22: Valor FLAT subtraído de cada golpe recebido (mínimo 0). Não afeta dano perfurante nem puro.
B23: Defesa (ação universal) | C23: Toda unidade tem. 1 orbe livre, recarga 4, gasta a ação: Invulnerável por 1 turno. Não é uma Habilidade, então Silenciar não a bloqueia — mas Atordoar sim.
B24: Invulnerável | C24: Imune a dano NOVO e a efeitos NOVOS pela duração. Continua podendo ser alvo. DoT já aplicado (Veneno, Queimadura, Sangramento, Maldição, Podridão) CONTINUA a contar — é a brecha desenhada, e é o que impede a rotação de Defesa de anular a ofensiva.
B25: Inalvejável | C25: Não pode ser escolhido como alvo de habilidade de alvo único. Área ainda atinge.
B26: Imunidade a controle | C26: Ignora tudo da seção CONTROLE pela duração.
B27: Imunidade a morte | C27: Não cai abaixo de 1 de HP pela duração.
B28: Vida Extra | C28: Ao cair, revive imediatamente com o HP indicado. Uma vez.
B29: Contra-ataque | C29: Ao ser atingido por alvo único, devolve o dano indicado automaticamente. Não gasta ação.
B30: Interceptar | C30: Redireciona para si o dano dirigido a outro aliado.
B31: Isca | C31: Unidade falsa que absorve o próximo ataque de alvo único contra o time.
A33: DANO CONTÍNUO (sempre dano puro)
B34: Efeito | C34: Regra
B35: Veneno / Queimadura / Sangramento | C35: Dano no início do turno do alvo. Mesma mecânica, nomes distintos porque kits leem cada um.
B36: Maldição de Yomi | C36: DoT que se espalha para as unidades vizinhas via a Habilidade de Izanami.
B37: Podridão | C37: DoT que também reduz o HP MÁXIMO do alvo em 10 por acúmulo. Só Itzamná restaura HP máximo perdido.
B38: Torpor | C38: Quando o alvo age, quem aplicou rouba HP e orbe dele.
A40: MODIFICADORES
B41: Efeito | C41: Regra
B42: +dano / −dano | C42: Valor flat somado ou subtraído do dano que a unidade CAUSA. Sempre com duração.
B43: Marca | C43: O alvo recebe dano extra de todas as fontes, ou habilita uma condição definida no kit.
B44: Encharcado | C44: O alvo recebe +5 de dano de Maré e Tempestade e serve de gatilho: muitos kits têm bônus contra Encharcados (dano dobrado, atordoar, executar). Padrão 2 turnos.
...

Sheet Recursos de Campo
A1: RECURSOS DE CAMPO — contadores compartilhados
A2: São os sistemas que fazem um time ter sinergia interna. Cada um pertence a um grupo pequeno de deuses e é o que dá razão para montar time temático em vez de juntar as 3 unidades mais fortes.
A4: Recurso | B4: Quem usa | C4: Regra
A5: DIA / NOITE | B5: Amaterasu, Tsukuyomi, Hou Yi, Lugh, Chang'e, Boto, Itzamná | C5: Estado global e exclusivo: ativar um cancela o outro. DIA: aliados Aurora +8 de dano, inimigos Umbra causam 5 menos. NOITE: o espelho. Dura 3 turnos. Hou Yi remove o DIA com a Habilidade — é a resposta desenhada.
A6: Combo | B6: Susanoo, Raijin, Fujin, Oni, Yamato Takeru | C6: Pool do TIME, não da unidade. Acumula com ataques; Susanoo e Yamato consomem tudo num finalizador. Teto 20. Time japonês inteiro escala junto.
A7: Disco Solar | B7: Rá (e Mnevis por sinergia) | C7: Só de Rá. Ganha 1 por turno e mais pelas habilidades, máx. 6. O Olho de Rá consome todos e escala. Recompensa paciência.
A8: Caudas | B8: Kitsune (Inari dá 1 de graça) | C8: Kitsune ganha 1 a cada 2 turnos, máx. 9. Cada 3 Caudas dão 5 de redução de dano; Nove Caudas escala com o total. Partida longa favorece ela.
A9: Atadura | B9: Anúbis | C9: Acumula no inimigo. Com 4, ele fica Selado por 2 turnos. Cada Atadura também dá +2 de dano recebido e bloqueia revive.
A10: Marca de Pedra | B10: Medusa | C10: Acumula no inimigo. Com 3, Petrifica por 1 turno e zera. Controle que o oponente vê chegando — e por isso é justo.
A11: Maldição de Yomi | B11: Izanami (Izanagi é a resposta) | C11: Acumula e se espalha. Portal de Yomotsu executa amaldiçoados abaixo de 25 de HP. Izanagi imuniza o time inteiro.
A12: Podridão | B12: Ah Puch | C12: Acumula e reduz HP MÁXIMO em 10 por acúmulo — dano que a cura não desfaz. Só Itzamná restaura.
A13: Livro da Vida e Morte | B13: Yan Wong | C13: Contagem de 3 turnos que executa se não for removida. Cria um relógio: o oponente tem que gastar remoção ou morrer.

Sheet Aquisição
A1: AQUISIÇÃO — gacha sem poder
A2: Princípio: o gacha vende ACESSO e OPÇÕES, nunca números. Duas rotas para todo deus — invocar (rápido, pago) ou Provação (grátis, exige habilidade). Nenhuma cópia, item ou moeda deste sistema altera um único ponto de dano.
A4: Rota 1 — Invocação (gacha)
A5: Parâmetro | B5: Valor | C5: Nota
A6: Custo por invocação | B6: 150 Gema | C6: Herdado do original.
A7: Invocação de 10 | B7: 1350 Gema | C7: Desconto de 10%.
A8: Faixas de invocação | B8: Nível A / S / SS | C8: Renomeado de 3★/4★/5★ para deixar claro que é COMPLEXIDADE de kit, não força. SS = kit com 3+ peças móveis. Nunca aparece na tela de partida.
A9: Taxa — SS | B9: 3% | C9: Subiu de 1,5%. Como não existe mais poder por raridade, taxa baixa só gera frustração sem proteger balanceamento.
A10: Taxa — S | B10: 17%
A11: Taxa — A | B11: 80%
A12: Pity (garantia) | B12: 60 invocações | C12: Muito mais curto que os ~133 do original. Aqui o teto não é opcional: sem ele, o jogador f2p simplesmente não acessa counters.
A13: Rotação gratuita | B13: 8 deuses / semana | C13: Liberados para todos. Reduz a barreira do novato E funciona como demonstração de venda. Copiado do que funciona em jogos de arena.
A14: Aluguel no ranqueado | B14: 1 slot | C14: Alavanca opcional: o jogador pode alugar 1 deus que não possui em cada partida ranqueada. Mata o argumento de pay-to-win de raiz, ao custo de pressão de coleção.
A16: Cópias repetidas — o que fazer com elas
